{"trial_id": "0", "hyperparameters": {"space": [{"class_name": "Int", "config": {"name": "units", "default": null, "conditions": [], "min_value": 32, "max_value": 128, "step": 32, "sampling": "linear"}}, {"class_name": "Choice", "config": {"name": "learning_rate", "default": 0.01, "conditions": [], "values": [0.01, 0.001, 0.0001], "ordered": true}}], "values": {"units": 32, "learning_rate": 0.001}}, "metrics": {"metrics": {}}, "score": null, "best_step": 0, "status": "FAILED", "message": "Traceback (most recent call last):\n  File \"/home/alish/.pyenv/versions/3.10.6/envs/predicting_land_cover/lib/python3.10/site-packages/keras_tuner/src/engine/base_tuner.py\", line 274, in _try_run_and_update_trial\n    self._run_and_update_trial(trial, *fit_args, **fit_kwargs)\n  File \"/home/alish/.pyenv/versions/3.10.6/envs/predicting_land_cover/lib/python3.10/site-packages/keras_tuner/src/engine/base_tuner.py\", line 239, in _run_and_update_trial\n    results = self.run_trial(trial, *fit_args, **fit_kwargs)\n  File \"/home/alish/.pyenv/versions/3.10.6/envs/predicting_land_cover/lib/python3.10/site-packages/keras_tuner/src/engine/tuner.py\", line 314, in run_trial\n    obj_value = self._build_and_fit_model(trial, *args, **copied_kwargs)\n  File \"/home/alish/.pyenv/versions/3.10.6/envs/predicting_land_cover/lib/python3.10/site-packages/keras_tuner/src/engine/tuner.py\", line 233, in _build_and_fit_model\n    results = self.hypermodel.fit(hp, model, *args, **kwargs)\n  File \"/home/alish/.pyenv/versions/3.10.6/envs/predicting_land_cover/lib/python3.10/site-packages/keras_tuner/src/engine/hypermodel.py\", line 149, in fit\n    return model.fit(*args, **kwargs)\n  File \"/home/alish/.pyenv/versions/3.10.6/envs/predicting_land_cover/lib/python3.10/site-packages/keras/src/utils/traceback_utils.py\", line 122, in error_handler\n    raise e.with_traceback(filtered_tb) from None\n  File \"/home/alish/.pyenv/versions/3.10.6/envs/predicting_land_cover/lib/python3.10/site-packages/tensorflow/python/eager/execute.py\", line 53, in quick_execute\n    tensors = pywrap_tfe.TFE_Py_Execute(ctx._handle, device_name, op_name,\ntensorflow.python.framework.errors_impl.InvalidArgumentError: Graph execution error:\n\nDetected at node gradient_tape/compile_loss/mse/sub/BroadcastGradientArgs defined at (most recent call last):\n  File \"/home/alish/.pyenv/versions/3.10.6/lib/python3.10/runpy.py\", line 196, in _run_module_as_main\n\n  File \"/home/alish/.pyenv/versions/3.10.6/lib/python3.10/runpy.py\", line 86, in _run_code\n\n  File \"/home/alish/.pyenv/versions/3.10.6/envs/predicting_land_cover/lib/python3.10/site-packages/ipykernel_launcher.py\", line 17, in <module>\n\n  File \"/home/alish/.pyenv/versions/3.10.6/envs/predicting_land_cover/lib/python3.10/site-packages/traitlets/config/application.py\", line 1075, in launch_instance\n\n  File \"/home/alish/.pyenv/versions/3.10.6/envs/predicting_land_cover/lib/python3.10/site-packages/ipykernel/kernelapp.py\", line 724, in start\n\n  File \"/home/alish/.pyenv/versions/3.10.6/envs/predicting_land_cover/lib/python3.10/site-packages/tornado/platform/asyncio.py\", line 205, in start\n\n  File \"/home/alish/.pyenv/versions/3.10.6/lib/python3.10/asyncio/base_events.py\", line 600, in run_forever\n\n  File \"/home/alish/.pyenv/versions/3.10.6/lib/python3.10/asyncio/base_events.py\", line 1896, in _run_once\n\n  File \"/home/alish/.pyenv/versions/3.10.6/lib/python3.10/asyncio/events.py\", line 80, in _run\n\n  File \"/home/alish/.pyenv/versions/3.10.6/envs/predicting_land_cover/lib/python3.10/site-packages/ipykernel/kernelbase.py\", line 512, in dispatch_queue\n\n  File \"/home/alish/.pyenv/versions/3.10.6/envs/predicting_land_cover/lib/python3.10/site-packages/ipykernel/kernelbase.py\", line 501, in process_one\n\n  File \"/home/alish/.pyenv/versions/3.10.6/envs/predicting_land_cover/lib/python3.10/site-packages/ipykernel/kernelbase.py\", line 408, in dispatch_shell\n\n  File \"/home/alish/.pyenv/versions/3.10.6/envs/predicting_land_cover/lib/python3.10/site-packages/ipykernel/kernelbase.py\", line 731, in execute_request\n\n  File \"/home/alish/.pyenv/versions/3.10.6/envs/predicting_land_cover/lib/python3.10/site-packages/ipykernel/ipkernel.py\", line 417, in do_execute\n\n  File \"/home/alish/.pyenv/versions/3.10.6/envs/predicting_land_cover/lib/python3.10/site-packages/ipykernel/zmqshell.py\", line 540, in run_cell\n\n  File \"/home/alish/.pyenv/versions/3.10.6/envs/predicting_land_cover/lib/python3.10/site-packages/IPython/core/interactiveshell.py\", line 3075, in run_cell\n\n  File \"/home/alish/.pyenv/versions/3.10.6/envs/predicting_land_cover/lib/python3.10/site-packages/IPython/core/interactiveshell.py\", line 3130, in _run_cell\n\n  File \"/home/alish/.pyenv/versions/3.10.6/envs/predicting_land_cover/lib/python3.10/site-packages/IPython/core/async_helpers.py\", line 129, in _pseudo_sync_runner\n\n  File \"/home/alish/.pyenv/versions/3.10.6/envs/predicting_land_cover/lib/python3.10/site-packages/IPython/core/interactiveshell.py\", line 3334, in run_cell_async\n\n  File \"/home/alish/.pyenv/versions/3.10.6/envs/predicting_land_cover/lib/python3.10/site-packages/IPython/core/interactiveshell.py\", line 3517, in run_ast_nodes\n\n  File \"/home/alish/.pyenv/versions/3.10.6/envs/predicting_land_cover/lib/python3.10/site-packages/IPython/core/interactiveshell.py\", line 3577, in run_code\n\n  File \"/tmp/ipykernel_134383/3654309957.py\", line 30, in <module>\n\n  File \"/home/alish/.pyenv/versions/3.10.6/envs/predicting_land_cover/lib/python3.10/site-packages/keras_tuner/src/engine/base_tuner.py\", line 234, in search\n\n  File \"/home/alish/.pyenv/versions/3.10.6/envs/predicting_land_cover/lib/python3.10/site-packages/keras_tuner/src/engine/base_tuner.py\", line 274, in _try_run_and_update_trial\n\n  File \"/home/alish/.pyenv/versions/3.10.6/envs/predicting_land_cover/lib/python3.10/site-packages/keras_tuner/src/engine/base_tuner.py\", line 239, in _run_and_update_trial\n\n  File \"/home/alish/.pyenv/versions/3.10.6/envs/predicting_land_cover/lib/python3.10/site-packages/keras_tuner/src/engine/tuner.py\", line 314, in run_trial\n\n  File \"/home/alish/.pyenv/versions/3.10.6/envs/predicting_land_cover/lib/python3.10/site-packages/keras_tuner/src/engine/tuner.py\", line 233, in _build_and_fit_model\n\n  File \"/home/alish/.pyenv/versions/3.10.6/envs/predicting_land_cover/lib/python3.10/site-packages/keras_tuner/src/engine/hypermodel.py\", line 149, in fit\n\n  File \"/home/alish/.pyenv/versions/3.10.6/envs/predicting_land_cover/lib/python3.10/site-packages/keras/src/utils/traceback_utils.py\", line 117, in error_handler\n\n  File \"/home/alish/.pyenv/versions/3.10.6/envs/predicting_land_cover/lib/python3.10/site-packages/keras/src/backend/tensorflow/trainer.py\", line 314, in fit\n\n  File \"/home/alish/.pyenv/versions/3.10.6/envs/predicting_land_cover/lib/python3.10/site-packages/keras/src/backend/tensorflow/trainer.py\", line 117, in one_step_on_iterator\n\n  File \"/home/alish/.pyenv/versions/3.10.6/envs/predicting_land_cover/lib/python3.10/site-packages/keras/src/backend/tensorflow/trainer.py\", line 104, in one_step_on_data\n\n  File \"/home/alish/.pyenv/versions/3.10.6/envs/predicting_land_cover/lib/python3.10/site-packages/keras/src/backend/tensorflow/trainer.py\", line 66, in train_step\n\nIncompatible shapes: [32,36,9] vs. [32,9]\n\t [[{{node gradient_tape/compile_loss/mse/sub/BroadcastGradientArgs}}]] [Op:__inference_one_step_on_iterator_46143]\n"}